2025-09-22 14:33:56 - root - INFO - [logging_config.py:51] - Logging configurado. Arquivo: C:\Users\Pedro Diniz\Documents\CadVision\CadVision_app\backend\logs\cadvision_20250922_143355.log
2025-09-22 14:33:56 - app - INFO - [logging_config.py:68] - EVENT: startup - DATA: {'timestamp': '2025-09-22T14:33:56.361561', 'service': 'app', 'event': 'startup', 'data': {'version': '1.1.0'}}
2025-09-22 14:33:56 - app.database - INFO - [database.py:172] - Banco de dados inicializado com sucesso (com novo schema).
2025-09-22 14:33:56 - app - INFO - [logging_config.py:68] - EVENT: database_initialized - DATA: {'timestamp': '2025-09-22T14:33:56.364561', 'service': 'app', 'event': 'database_initialized', 'data': {}}
2025-09-22 14:34:07 - vision/identify - INFO - [logging_config.py:68] - EVENT: process_started - DATA: {'timestamp': '2025-09-22T14:34:07.823840', 'service': 'vision/identify', 'event': 'process_started', 'data': {'vertical': 'vestuario', 'filename': 'Imagem do WhatsApp de 2025-09-21 à(s) 16.46.16_17ae13c9.jpg', 'content_type': 'image/jpeg'}}
2025-09-22 14:34:07 - vision/identify - INFO - [logging_config.py:68] - EVENT: image_loaded - DATA: {'timestamp': '2025-09-22T14:34:07.824838', 'service': 'vision/identify', 'event': 'image_loaded', 'data': {'size_bytes': 102525, 'hash': 'b2fc004d6c9b4e068ae9234462176855'}}
2025-09-22 14:34:07 - vision/identify - INFO - [logging_config.py:68] - EVENT: vision_extraction_start - DATA: {'timestamp': '2025-09-22T14:34:07.825838', 'service': 'vision/identify', 'event': 'vision_extraction_start', 'data': {}}
2025-09-22 14:34:07 - app.services.vision_service - INFO - [vision_service.py:108] - Imagem aprimorada para OCR.
2025-09-22 14:34:10 - app.services.vision_service - INFO - [vision_service.py:181] - Vision API: Texto extraído (156 chars), Logos: 0, Labels: 0
2025-09-22 14:34:10 - app.services.vision_service - INFO - [vision_service.py:276] - Texto bruto: '100% ALGODÃO
DECOTE: 98% ALGODÃO
2% ELASTANO
FORNECEDOR: 84891
Modelo: 1059827 - T. 20
40
P W
P
日
Cor VERDE CLARO
000000113667090314
SKU: 11366709
PO:288843' -> Texto limpo para análise: '100982848911059827204000000011366709031411366709288843'
2025-09-22 14:34:10 - app.services.vision_service - WARNING - [vision_service.py:297] - Nenhum GTIN válido encontrado no texto limpo: '100982848911059827204000000011366709031411366709288843'
2025-09-22 14:34:10 - vision/identify - INFO - [logging_config.py:68] - EVENT: vision_extraction_complete - DATA: {'timestamp': '2025-09-22T14:34:10.447463', 'service': 'vision/identify', 'event': 'vision_extraction_complete', 'data': {'success': True, 'text_length': 156, 'gtin_found': False}}
2025-09-22 14:34:10 - vision/identify - INFO - [logging_config.py:68] - EVENT: intelligent_analysis_start - DATA: {'timestamp': '2025-09-22T14:34:10.448463', 'service': 'vision/identify', 'event': 'intelligent_analysis_start', 'data': {'vertical': 'vestuario'}}
2025-09-22 14:34:10 - app.services.product_service - INFO - [product_service.py:64] - Etapa 1 falhou ou não aplicável. Iniciando Etapa 2 (Inferência da IA).
2025-09-22 14:34:12 - ai_service - INFO - [logging_config.py:68] - EVENT: json_parsed_successfully - DATA: {'timestamp': '2025-09-22T14:34:12.402115', 'service': 'ai_service', 'event': 'json_parsed_successfully', 'data': {'title_extracted': 'Camiseta', 'brand_extracted': None, 'category_extracted': 'Vestuário'}}
2025-09-22 14:34:12 - app.services.product_service - INFO - [product_service.py:77] - Produto identificado: Camiseta
2025-09-22 14:34:12 - vision/identify - INFO - [logging_config.py:68] - EVENT: intelligent_analysis_complete - DATA: {'timestamp': '2025-09-22T14:34:12.403132', 'service': 'vision/identify', 'event': 'intelligent_analysis_complete', 'data': {'title': 'Camiseta', 'brand': None}}
2025-09-22 14:34:12 - main - ERROR - [main.py:481] - Erro não tratado na rota http://127.0.0.1:8000/api/v1/vision/identify: 1 validation error for IdentifiedProduct
gtin
  Value error, GTIN deve ter 8, 12, 13 ou 14 dígitos [type=value_error, input_value='000000113667090314', input_type=str]
    For further information visit https://errors.pydantic.dev/2.11/v/value_error
Traceback (most recent call last):
  File "C:\Users\Pedro Diniz\Documents\CadVision\CadVision_app\backend\venv\Lib\site-packages\starlette\middleware\errors.py", line 164, in __call__
    await self.app(scope, receive, _send)
  File "C:\Users\Pedro Diniz\Documents\CadVision\CadVision_app\backend\venv\Lib\site-packages\starlette\middleware\gzip.py", line 24, in __call__
    await responder(scope, receive, send)
  File "C:\Users\Pedro Diniz\Documents\CadVision\CadVision_app\backend\venv\Lib\site-packages\starlette\middleware\gzip.py", line 44, in __call__
    await self.app(scope, receive, self.send_with_gzip)
  File "C:\Users\Pedro Diniz\Documents\CadVision\CadVision_app\backend\venv\Lib\site-packages\starlette\middleware\cors.py", line 93, in __call__
    await self.simple_response(scope, receive, send, request_headers=headers)
  File "C:\Users\Pedro Diniz\Documents\CadVision\CadVision_app\backend\venv\Lib\site-packages\starlette\middleware\cors.py", line 148, in simple_response
    await self.app(scope, receive, send)
  File "C:\Users\Pedro Diniz\Documents\CadVision\CadVision_app\backend\venv\Lib\site-packages\starlette\middleware\exceptions.py", line 65, in __call__
    await wrap_app_handling_exceptions(self.app, conn)(scope, receive, send)
  File "C:\Users\Pedro Diniz\Documents\CadVision\CadVision_app\backend\venv\Lib\site-packages\starlette\_exception_handler.py", line 64, in wrapped_app
    raise exc
  File "C:\Users\Pedro Diniz\Documents\CadVision\CadVision_app\backend\venv\Lib\site-packages\starlette\_exception_handler.py", line 53, in wrapped_app
    await app(scope, receive, sender)
  File "C:\Users\Pedro Diniz\Documents\CadVision\CadVision_app\backend\venv\Lib\site-packages\starlette\routing.py", line 756, in __call__
    await self.middleware_stack(scope, receive, send)
  File "C:\Users\Pedro Diniz\Documents\CadVision\CadVision_app\backend\venv\Lib\site-packages\starlette\routing.py", line 776, in app
    await route.handle(scope, receive, send)
  File "C:\Users\Pedro Diniz\Documents\CadVision\CadVision_app\backend\venv\Lib\site-packages\starlette\routing.py", line 297, in handle
    await self.app(scope, receive, send)
  File "C:\Users\Pedro Diniz\Documents\CadVision\CadVision_app\backend\venv\Lib\site-packages\starlette\routing.py", line 77, in app
    await wrap_app_handling_exceptions(app, request)(scope, receive, send)
  File "C:\Users\Pedro Diniz\Documents\CadVision\CadVision_app\backend\venv\Lib\site-packages\starlette\_exception_handler.py", line 64, in wrapped_app
    raise exc
  File "C:\Users\Pedro Diniz\Documents\CadVision\CadVision_app\backend\venv\Lib\site-packages\starlette\_exception_handler.py", line 53, in wrapped_app
    await app(scope, receive, sender)
  File "C:\Users\Pedro Diniz\Documents\CadVision\CadVision_app\backend\venv\Lib\site-packages\starlette\routing.py", line 72, in app
    response = await func(request)
               ^^^^^^^^^^^^^^^^^^^
  File "C:\Users\Pedro Diniz\Documents\CadVision\CadVision_app\backend\venv\Lib\site-packages\fastapi\routing.py", line 278, in app
    raw_response = await run_endpoint_function(
                   ^^^^^^^^^^^^^^^^^^^^^^^^^^^^
  File "C:\Users\Pedro Diniz\Documents\CadVision\CadVision_app\backend\venv\Lib\site-packages\fastapi\routing.py", line 191, in run_endpoint_function
    return await dependant.call(**values)
           ^^^^^^^^^^^^^^^^^^^^^^^^^^^^^^
  File "C:\Users\Pedro Diniz\Documents\CadVision\CadVision_app\backend\main.py", line 163, in identify_image
    identified_product = models.IdentifiedProduct(**product_info)
                         ^^^^^^^^^^^^^^^^^^^^^^^^^^^^^^^^^^^^^^^^
  File "C:\Users\Pedro Diniz\Documents\CadVision\CadVision_app\backend\venv\Lib\site-packages\pydantic\main.py", line 253, in __init__
    validated_self = self.__pydantic_validator__.validate_python(data, self_instance=self)
                     ^^^^^^^^^^^^^^^^^^^^^^^^^^^^^^^^^^^^^^^^^^^^^^^^^^^^^^^^^^^^^^^^^^^^^
pydantic_core._pydantic_core.ValidationError: 1 validation error for IdentifiedProduct
gtin
  Value error, GTIN deve ter 8, 12, 13 ou 14 dígitos [type=value_error, input_value='000000113667090314', input_type=str]
    For further information visit https://errors.pydantic.dev/2.11/v/value_error
2025-09-22 14:41:20 - app - INFO - [logging_config.py:68] - EVENT: shutdown - DATA: {'timestamp': '2025-09-22T14:41:20.392956', 'service': 'app', 'event': 'shutdown', 'data': {}}
2025-09-22 14:41:20 - main - INFO - [main.py:45] - Encerrando aplicação CadVision API.
